Traceback (most recent call last):
  File "/mnt/vast-standard/home/stein65/u14374/miniforge3/envs/modified_lm_eval_env/lib/python3.9/site-packages/pandas/core/groupby/groupby.py", line 1825, in apply
    result = self._python_apply_general(f, self._selected_obj)
  File "/mnt/vast-standard/home/stein65/u14374/miniforge3/envs/modified_lm_eval_env/lib/python3.9/site-packages/pandas/core/groupby/groupby.py", line 1886, in _python_apply_general
    values, mutated = self._grouper.apply_groupwise(f, data, self.axis)
  File "/mnt/vast-standard/home/stein65/u14374/miniforge3/envs/modified_lm_eval_env/lib/python3.9/site-packages/pandas/core/groupby/ops.py", line 919, in apply_groupwise
    res = f(group)
  File "/mnt/vast-standard/home/stein65/u14374/miniforge3/envs/modified_lm_eval_env/lib/python3.9/site-packages/pandas/core/groupby/groupby.py", line 1810, in f
    return func(g, *args, **kwargs)
TypeError: <lambda>() got an unexpected keyword argument 'group_keys'

During handling of the above exception, another exception occurred:

Traceback (most recent call last):
  File "/scratch-scc/users/u14374/bachelorarbeit/bachelorthesis_multilingual_steering/src/translate_or_bench.py", line 225, in <module>
    df = sample_or_bench(df,n_samples=SAMPLESIZE)
  File "/scratch-scc/users/u14374/bachelorarbeit/bachelorthesis_multilingual_steering/src/translate_or_bench.py", line 81, in sample_or_bench
    sampled_df = or_df.groupby(or_df['category']).apply(
  File "/mnt/vast-standard/home/stein65/u14374/miniforge3/envs/modified_lm_eval_env/lib/python3.9/site-packages/pandas/core/groupby/groupby.py", line 1847, in apply
    return self._python_apply_general(f, self._obj_with_exclusions)
  File "/mnt/vast-standard/home/stein65/u14374/miniforge3/envs/modified_lm_eval_env/lib/python3.9/site-packages/pandas/core/groupby/groupby.py", line 1886, in _python_apply_general
    values, mutated = self._grouper.apply_groupwise(f, data, self.axis)
  File "/mnt/vast-standard/home/stein65/u14374/miniforge3/envs/modified_lm_eval_env/lib/python3.9/site-packages/pandas/core/groupby/ops.py", line 919, in apply_groupwise
    res = f(group)
  File "/mnt/vast-standard/home/stein65/u14374/miniforge3/envs/modified_lm_eval_env/lib/python3.9/site-packages/pandas/core/groupby/groupby.py", line 1810, in f
    return func(g, *args, **kwargs)
TypeError: <lambda>() got an unexpected keyword argument 'group_keys'
